函数在调试和运行过程中如果出现异常，腾讯云 SCF 平台会尽最大可能捕获气场并将异常信息写入日志中。函数运行产生的异常包括捕获的异常（Handled error）和未捕获的异常（Unhandled Error）。例如，用户可以在代码中显式地抛出异常：

```
def always_failed_handler(event):
    raise Exception('I failed!')
```

此函数在运行过程中将引发异常，返回下面的错误信息：
```
{
  "errorMessage": "I failed!",
  "stackTrace": [
    [
      "/var/task/lambda_function.py",
      3,
      "my_always_fails_handler",
      "raise Exception('I failed!')"
    ]
  ],
  "errorType": "Exception"
}
```
SCF 平台会将此错误信息记录到函数日志中。您还可在 CloudWatch 指标中查看错误指标。

如果您需要测试此代码，请新建函数并复制上面的函数代码，不添加任何触发器。点击控制台【测试】按钮，选择“Hello　World”测试示例进行测试。

您可以在代码中自行定义如何处理可能出现的错误，保障应用程序的健壮性和可扩展型。例如：继承Exception类

```
class UserNameAlreadyExistsException(Exception): pass
            
def create_user(event):
    raise UserNameAlreadyExistsException('The username already exists,please change a name!')
```

或者使用 Catch 语句捕获错误：

```
def create_user(event):
    try:
        createUser(event[username],event[pwd])
    catch:
        //catch error and do something
``   
     
当用户的代码逻辑中未进行错误捕获时，SCF 会尽可能捕获错误。但遇到平台也无法捕捉的错误时，例如用户函数在运行过程中突然崩溃退出，系统将会返回一个通用的错误消息。

下表展示了代码运行中常见的一些错误

|错误场景|返回消息|
|--|--|
|使用 raise 抛出异常|	{“errorMessage”: “sth”, “errorType”: “Error”, “stackTrace”: [“ (/var/task/index.py)”]}|
|处理方法不存在|	{“errorMessage”: “'module' object has no attribute 'abc'”}|
|依赖模块并不存在|{“errorMessage”: “Cannot find module ‘/code/index.py”}|
|超时|{“errorMessage”: “time out”}|